Workbook

Sheet Org Summary
A2: accenINDIA – PEOPLE & ORGANIZATION DASHBOARD
A3: Sample Data · Data & AI Practice (Illustrative)
A6: Total Employees (Sample) | B6: Active Projects | C6: Skills in Catalog | D6: Certifications Issued | F6: Avg Experience (Yrs) | G6: Active Employees | H6: Training Records
A7: =COUNTA(Employees!A2:A152) -> 151 | B7: =COUNTIF(Projects!F2:F16,"Active") -> 9 | C7: =COUNTA('Skills Catalog'!A2:A41) -> 40 | D7: =COUNTA(Certifications!A2:A108) -> 107 | F7: =ROUND(AVERAGE(Employees!AD2:AD152),1) -> 3.3 | G7: =COUNTIF(Employees!U2:U999,"Active") -> 142 | H7: =COUNTA('Training Records'!A2:A454) -> 453
A9: HEADCOUNT BY CAREER LEVEL
A10: Career Level | B10: Designation | C10: Headcount | D10: % of Total | F10: Department | G10: Dept ID | H10: Headcount
A11: Level 1 – Global Managing Director | B11: Global Managing Director | C11: =COUNTIF(Employees!$H:$H,1) -> 1 | D11: =IF(B7>0,C11/B7,0) -> 0.11111111 | F11: Data & AI | G11: DEPT001 | H11: =COUNTIF(Employees!$L:$L,"DEPT001") -> 47
A12: Level 2 – Senior Managing Director | B12: Senior Managing Director | C12: =COUNTIF(Employees!$H:$H,2) -> 1 | D12: =IF(B7>0,C12/B7,0) -> 0.11111111 | F12: Cloud & Infrastructure | G12: DEPT002 | H12: =COUNTIF(Employees!$L:$L,"DEPT002") -> 24
A13: Level 3 – Managing Director | B13: Managing Director | C13: =COUNTIF(Employees!$H:$H,3) -> 1 | D13: =IF(B7>0,C13/B7,0) -> 0.11111111 | F13: Cybersecurity | G13: DEPT003 | H13: =COUNTIF(Employees!$L:$L,"DEPT003") -> 9
A14: Level 4 – Director | B14: Director | C14: =COUNTIF(Employees!$H:$H,4) -> 3 | D14: =IF(B7>0,C14/B7,0) -> 0.33333333 | F14: Digital Commerce | G14: DEPT004 | H14: =COUNTIF(Employees!$L:$L,"DEPT004") -> 12
A15: Level 5 – Associate Director | B15: Associate Director | C15: =COUNTIF(Employees!$H:$H,5) -> 5 | D15: =IF(B7>0,C15/B7,0) -> 0.55555556 | F15: Enterprise Platforms | G15: DEPT005 | H15: =COUNTIF(Employees!$L:$L,"DEPT005") -> 14
A16: Level 6 – Senior Manager | B16: Senior Manager | C16: =COUNTIF(Employees!$H:$H,6) -> 8 | D16: =IF(B7>0,C16/B7,0) -> 0.88888889 | F16: Finance & Risk | G16: DEPT006 | H16: =COUNTIF(Employees!$L:$L,"DEPT006") -> 8
A17: Level 7 – Manager | B17: Manager | C17: =COUNTIF(Employees!$H:$H,7) -> 12 | D17: =IF(B7>0,C17/B7,0) -> 1.3333333 | F17: Supply Chain & Operations | G17: DEPT007 | H17: =COUNTIF(Employees!$L:$L,"DEPT007") -> 5
A18: Level 8 – Associate Manager | B18: Associate Manager | C18: =COUNTIF(Employees!$H:$H,8) -> 15 | D18: =IF(B7>0,C18/B7,0) -> 1.6666667 | F18: Human Capital Mgmt | G18: DEPT008 | H18: =COUNTIF(Employees!$L:$L,"DEPT008") -> 6
A19: Level 9 – Team Lead / Specialist | B19: Team Lead / Specialist | C19: =COUNTIF(Employees!$H:$H,9) -> 20 | D19: =IF(B7>0,C19/B7,0) -> 2.2222222 | F19: Strategy & Consulting | G19: DEPT009 | H19: =COUNTIF(Employees!$L:$L,"DEPT009") -> 13
A20: Level 10 – Senior Software Engineer | B20: Senior Software Engineer | C20: =COUNTIF(Employees!$H:$H,10) -> 25 | D20: =IF(B7>0,C20/B7,0) -> 2.7777778 | F20: Intelligent Automation | G20: DEPT010 | H20: =COUNTIF(Employees!$L:$L,"DEPT010") -> 13
A21: Level 11 – Software Engineer | B21: Software Engineer | C21: =COUNTIF(Employees!$H:$H,11) -> 30 | D21: =IF(B7>0,C21/B7,0) -> 3.3333333 | F21: TOTAL | H21: =SUM(H11:H20) -> 151
A22: Level 12 – Associate Software Engineer | B22: Associate Software Engineer | C22: =COUNTIF(Employees!$H:$H,12) -> 30 | D22: =IF(B7>0,C22/B7,0) -> 3.3333333
A23: TOTAL | C23: =SUM(C11:C22) -> 151
A26: PROJECT PORTFOLIO SUMMARY
A27: Status | B27: Count | C27: Total Value (INR)
A28: Active | B28: =COUNTIF(Projects!$F:$F,"Active") -> 9 | C28: =SUMIF(Projects!$F:$F,"Active",Projects!$J:$J) -> 634000000
A29: Completed | B29: =COUNTIF(Projects!$F:$F,"Completed") -> 6 | C29: =SUMIF(Projects!$F:$F,"Completed",Projects!$J:$J) -> 369000000
A30: On Hold | B30: =COUNTIF(Projects!$F:$F,"On Hold") -> 0 | C30: =SUMIF(Projects!$F:$F,"On Hold",Projects!$J:$J) -> 0
A31: Cancelled | B31: =COUNTIF(Projects!$F:$F,"Cancelled") -> 0 | C31: =SUMIF(Projects!$F:$F,"Cancelled",Projects!$J:$J) -> 0
A33: WORKFORCE COMPOSITION
A34: Employment Status | B34: Count | D34: Work Mode | E34: Count
A35: Active | B35: =COUNTIF(Employees!$U:$U,"Active") -> 142 | D35: Hybrid | E35: =COUNTIF(Employees!$AB:$AB,"Hybrid") -> 84
A36: On Leave | B36: =COUNTIF(Employees!$U:$U,"On Leave") -> 6 | D36: Remote | E36: =COUNTIF(Employees!$AB:$AB,"Remote") -> 36
A37: Notice Period | B37: =COUNTIF(Employees!$U:$U,"Notice Period") -> 3 | D37: On-site | E37: =COUNTIF(Employees!$AB:$AB,"On-site") -> 31
A38: Terminated | B38: =COUNTIF(Employees!$U:$U,"Terminated") -> 0
A40: HEADCOUNT BY OFFICE / CITY
A41: City | B41: Country | C41: Region | D41: Headcount
A42: Mumbai | B42: India | C42: APAC | D42: =COUNTIF(Employees!$M:$M,"OFF001") -> 12
A43: Bangalore | B43: India | C43: APAC | D43: =COUNTIF(Employees!$M:$M,"OFF002") -> 37
A44: Hyderabad | B44: India | C44: APAC | D44: =COUNTIF(Employees!$M:$M,"OFF003") -> 16
A45: Pune | B45: India | C45: APAC | D45: =COUNTIF(Employees!$M:$M,"OFF004") -> 24
A46: Delhi NCR | B46: India | C46: APAC | D46: =COUNTIF(Employees!$M:$M,"OFF005") -> 27
A47: New York | B47: USA | C47: Americas | D47: =COUNTIF(Employees!$M:$M,"OFF006") -> 12
A48: London | B48: UK | C48: EMEA | D48: =COUNTIF(Employees!$M:$M,"OFF007") -> 8
...

Sheet Career Levels
A1: Level # | B1: Level Category | C1: Designation | D1: Min Exp (Yrs) | E1: Typical Span of Control | F1: Reports To | G1: Description
A2: 1 | B2: Leadership | C2: Global Managing Director | D2: 25 | E2: N/A | F2: N/A (Top Level) | G2: Shapes firm's global direction and strategy
A3: 2 | B3: Leadership | C3: Senior Managing Director | D3: 22 | E3: N/A | F3: Level 1 | G3: Cross-service-line senior leadership
A4: 3 | B4: Leadership | C4: Managing Director | D4: 20 | E4: Multiple Directors | F4: Level 2 | G4: P&L owner for a large practice or geography
A5: 4 | B5: Director | C5: Director | D5: 17 | E5: 4–6 Assoc. Directors | F5: Level 3 (Leadership) | G5: Manages large client accounts & portfolios
A6: 5 | B6: Associate Director | C6: Associate Director | D6: 14 | E6: 3–6 Sr Managers | F6: Level 4 (Director) | G6: Owns delivery of large engagements end-to-end
A7: 6 | B7: Senior Manager | C7: Senior Manager | D7: 11 | E7: 3–5 Managers | F7: Level 5 (Assoc. Director) | G7: Leads project workstreams; strong client presence
A8: 7 | B8: Manager | C8: Manager | D8: 8 | E8: 2–5 Assoc. Managers | F8: Level 6 (Sr Manager) | G8: Manages modules; mentors junior members
A9: 8 | B9: Associate Manager | C9: Associate Manager | D9: 6 | E9: 2–4 Team Leads | F9: Level 7 (Manager) | G9: Coordinates small sub-teams; rising manager
A10: 9 | B10: Team Lead/Specialist | C10: Team Lead / Specialist | D10: 4 | E10: 5–12 Engineers | F10: Level 8 (Assoc. Manager) | G10: Technical lead; owns day-to-day delivery for a squad
A11: 10 | B11: Senior Software Engineer | C11: Senior Software Engineer | D11: 3 | E11: None (IC) | F11: Level 9 (Team Lead) | G11: Senior individual contributor; mentors juniors
A12: 11 | B12: Software Engineer | C12: Software Engineer | D12: 1 | E12: None (IC) | F12: Level 9 (Team Lead) | G12: Core individual contributor
A13: 12 | B13: Associate Software Engineer | C13: Associate Software Engineer | D13: 0 | E13: None (IC) | F13: Level 9 (Team Lead) | G13: Entry-level engineer

Sheet Departments
A1: Department_ID | B1: Department_Name | C1: Service_Line | D1: Business_Group | E1: Cost_Center | F1: Practice_Head_EmpID | G1: Parent_Group
A2: DEPT001 | B2: Data & AI | C2: Technology | D2: Technology Group | E2: CC-DATA-001 | F2: EMP0001 | G2: Technology Group
A3: DEPT002 | B3: Cloud & Infrastructure | C3: Technology | D3: Technology Group | E3: CC-CLD-001 | F3: EMP0002 | G3: Technology Group
A4: DEPT003 | B4: Cybersecurity | C4: Technology | D4: Technology Group | E4: CC-SEC-001 | F4: EMP0003 | G4: Technology Group
A5: DEPT004 | B5: Digital Commerce | C5: Digital | D5: Digital Group | E5: CC-DIG-001 | F5: EMP0001 | G5: Digital Group
A6: DEPT005 | B6: Enterprise Platforms | C6: Enterprise | D6: Enterprise Group | E6: CC-ENT-001 | F6: EMP0002 | G6: Enterprise Group
A7: DEPT006 | B7: Finance & Risk | C7: Business Services | D7: Business Services Group | E7: CC-FIN-001 | F7: EMP0003 | G7: Business Services Group
A8: DEPT007 | B8: Supply Chain & Operations | C8: Business Services | D8: Business Services Group | E8: CC-SUP-001 | F8: EMP0001 | G8: Business Services Group
A9: DEPT008 | B9: Human Capital Mgmt | C9: Business Services | D9: Business Services Group | E9: CC-HCM-001 | F9: EMP0002 | G9: Business Services Group
A10: DEPT009 | B10: Strategy & Consulting | C10: Consulting | D10: Consulting Group | E10: CC-STR-001 | F10: EMP0003 | G10: Consulting Group
A11: DEPT010 | B11: Intelligent Automation | C11: Technology | D11: Technology Group | E11: CC-AUT-001 | F11: EMP0001 | G11: Technology Group

Sheet Offices
A1: Office_ID | B1: City | C1: Country | D1: Region | E1: Address | F1: Postal_Code | G1: Phone | H1: Is_HQ | I1: Time_Zone | J1: Seating_Capacity
A2: OFF001 | B2: Mumbai | C2: India | D2: APAC | E2: accen Tower, BKC, Mumbai 400051 | F2: 400051 | G2: +91-22-6678-0000 | H2: Yes | I2: IST (UTC+5:30) | J2: 12000
A3: OFF002 | B3: Bangalore | C3: India | D3: APAC | E3: Manyata Tech Park, Hebbal, Bangalore 560045 | F3: 560045 | G3: +91-80-4100-0000 | H3: No | I3: IST (UTC+5:30) | J3: 18000
A4: OFF003 | B4: Hyderabad | C4: India | D4: APAC | E4: Financial District, Nanakramguda, Hyderabad 500032 | F4: 500032 | G4: +91-40-6700-0000 | H4: No | I4: IST (UTC+5:30) | J4: 10000
A5: OFF004 | B5: Pune | C5: India | D5: APAC | E5: Magarpatta City, Pune 411013 | F5: 411013 | G5: +91-20-6601-0000 | H5: No | I5: IST (UTC+5:30) | J5: 8000
A6: OFF005 | B6: Delhi NCR | C6: India | D6: APAC | E6: DLF Cyber City, Gurugram 122002 | F6: 122002 | G6: +91-124-4600-0000 | H6: No | I6: IST (UTC+5:30) | J6: 9000
A7: OFF006 | B7: New York | C7: USA | D7: Americas | E7: 1345 Avenue of the Americas, NY 10105 | F7: 10105 | G7: +1-917-452-4400 | H7: No | I7: EST (UTC-5:00) | J7: 5000
A8: OFF007 | B8: London | C8: UK | D8: EMEA | E8: 30 Fenchurch Street, London EC3M 3BD | F8: EC3M 3BD | G8: +44-20-7844-4000 | H8: No | I8: GMT (UTC+0:00) | J8: 4000
A9: OFF008 | B9: Singapore | C9: Singapore | D9: APAC | E9: 1 Harbourfront Place, Singapore 098633 | F9: 098633 | G9: +65-6224-8210 | H9: No | I9: SGT (UTC+8:00) | J9: 3000
A10: OFF009 | B10: Sydney | C10: Australia | D10: APAC | E10: Level 10, Sydney Olympic Park, NSW 2127 | F10: 2127 | G10: +61-2-9005-5000 | H10: No | I10: AEDT (UTC+11:00) | J10: 2000
A11: OFF010 | B11: Dubai | C11: UAE | D11: EMEA | E11: DIFC Gate Village, Building 4, Dubai | F11: 00000 | G11: +971-4-567-8900 | H11: No | I11: GST (UTC+4:00) | J11: 1500

Sheet Skills Catalog
A1: Skill_ID | B1: Skill_Name | C1: Skill_Category | D1: Sub_Category | E1: Description
A2: SK001 | B2: Python | C2: Technical | D2: Programming Language | E2: Core scripting & data engineering language
A3: SK002 | B3: SQL | C3: Technical | D3: Database | E3: Querying and managing relational databases
A4: SK003 | B4: Apache Spark | C4: Technical | D4: Big Data | E4: Distributed data processing framework
A5: SK004 | B5: Apache Kafka | C5: Technical | D5: Streaming | E5: Real-time event streaming platform
A6: SK005 | B6: AWS | C6: Technical | D6: Cloud Platform | E6: Amazon Web Services cloud platform
A7: SK006 | B7: Azure | C7: Technical | D7: Cloud Platform | E7: Microsoft Azure cloud platform
A8: SK007 | B8: GCP | C8: Technical | D8: Cloud Platform | E8: Google Cloud Platform
A9: SK008 | B9: Machine Learning | C9: Technical | D9: AI/ML | E9: Supervised/unsupervised model development
A10: SK009 | B10: Deep Learning | C10: Technical | D10: AI/ML | E10: Neural networks, CNNs, RNNs, Transformers
A11: SK010 | B11: NLP / Generative AI | C11: Technical | D11: AI/ML | E11: Language models, RAG, LLM fine-tuning
A12: SK011 | B12: Power BI | C12: Technical | D12: BI/Analytics | E12: Microsoft Power BI dashboards & reports
... A41: SK040 | B41: Git / GitHub | C41: Tool | D41: Version Control | E41: Source code version control

Sheet Employees
A1: Employee_ID | B1: First_Name | C1: Last_Name | D1: Full_Name | E1: Gender | F1: Date_of_Birth | G1: Nationality | H1: Career_Level | I1: Level_Category | J1: Designation | K1: Employee_Band | L1: Department_ID | M1: Office_ID | N1: Manager_ID | O1: Work_Email | P1: Personal_Email | Q1: Work_Phone | R1: Mobile | S1: Date_of_Joining | T1: Employment_Type | U1: Employment_Status | V1: Education_Level | W1: University | X1: Degree | Y1: Annual_CTC_LPA | Z1: Currency | AA1: Notice_Period | AB1: Work_Mode | AC1: Cost_Center | AD1: Years_at_accen | AE1: Total_Exp_Yrs
A2: EMP0001 | B2: Rahul | C2: Kapoor | D2: Rahul Kapoor | E2: Male | F2: 25476 | G2: Indian | H2: 1 | I2: Leadership | J2: Global Managing Director | K2: L1 | L2: DEPT006 | M2: OFF005 | O2: rahul.kapoor@accen.com | P2: rahul.kapoor4@gmail.com | Q2: +91-9298308496 | R2: +91-9932781453 | S2: 43973 | T2: Permanent | U2: Active | V2: ME | W2: INSEAD | X2: Data Science | Y2: 487.46 | Z2: INR | AA2: 3 Months | AB2: Hybrid | AC2: CC-FIN-001 | AD2: 5 | AE2: 28
A3: EMP0002 | B3: Priya | C3: Rao | D3: Priya Rao | E3: Female | F3: 28428 | G3: Indian | H3: 2 | I3: Leadership | J3: Senior Managing Director | K3: L2 | L3: DEPT001 | M3: OFF002 | N3: EMP0001 | O3: priya.rao@accen.com | P3: priya.rao6@gmail.com | Q3: +91-9988581741 | R3: +91-9196230889 | S3: 43084 | T3: Permanent | U3: Active | V3: Ph.D | W3: LSE | X3: Information Technology | Y3: 368.79 | Z3: INR | AA3: 3 Months | AB3: Hybrid | AC3: CC-DATA-001 | AD3: 8 | AE3: 24
A4: EMP0003 | B4: Sophie | C4: Iyer | D4: Sophie Iyer | E4: Female | F4: 29184 | G4: Indian | H4: 3 | I4: Leadership | J4: Managing Director | K4: L3 | L4: DEPT005 | M4: OFF006 | N4: EMP0002 | O4: sophie.iyer@accen.com | P4: sophie.iyer21@gmail.com | Q4: +91-8516472528 | R4: +91-7858802729 | S4: 44608 | T4: Permanent | U4: Active | V4: M.Tech | W4: IIIT Hyderabad | X4: Information Technology | Y4: 268.01 | Z4: INR | AA4: 3 Months | AB4: On-site | AC4: CC-ENT-001 | AD4: 3 | AE4: 21
A5: EMP0004 | B5: Varun | C5: Tanaka | D5: Varun Tanaka | E5: Male | F5: 28949 | G5: Indian | H5: 4 | I5: Director | J5: Director | K5: L4 | L5: DEPT006 | M5: OFF002 | N5: EMP0003 | O5: varun.tanaka@accen.com | P5: varun.tanaka35@gmail.com | Q5: +91-7271321231 | R5: +91-9323852787 | S5: 44121 | T5: Permanent | U5: Active | V5: Ph.D | W5: MIT | X5: Data Science | Y5: 122.57 | Z5: INR | AA5: 3 Months | AB5: Hybrid | AC5: CC-FIN-001 | AD5: 6 | AE5: 20
A6: EMP0005 | B6: Ishita | C6: Aggarwal | D6: Ishita Aggarwal | E6: Female | F6: 28479 | G6: Indian | H6: 4 | I6: Director | J6: Director | K6: L4 | L6: DEPT007 | M6: OFF004 | N6: EMP0003 | O6: ishita.aggarwal@accen.com | P6: ishita.aggarwal66@gmail.com | Q6: +91-9021195325 | R6: +91-7192214975 | S6: 44449 | T6: Permanent | U6: Active | V6: MCA | W6: BITS Pilani | X6: Electronics Engineering | Y6: 137.55 | Z6: INR | AA6: 3 Months | AB6: On-site | AC6: CC-SUP-001 | AD6: 4 | AE6: 20
A7: EMP0006 | B7: Vikas | C7: Menon | D7: Vikas Menon | E7: Male | F7: 29835 | G7: British | H7: 4 | I7: Director | J7: Director | K7: L4 | L7: DEPT001 | M7: OFF004 | N7: EMP0003 | O7: vikas.menon@accen.com | P7: vikas.menon44@gmail.com | Q7: +91-7456407757 | R7: +91-8780265840 | S7: 42911 | T7: Permanent | U7: Active | V7: M.Tech | W7: IIM Bangalore | X7: Computer Science | Y7: 180.07 | Z7: INR | AA7: 3 Months | AB7: Remote | AC7: CC-DATA-001 | AD7: 9 | AE7: 19
A8: EMP0007 | B8: Christopher | C8: Mehta | D8: Christopher Mehta | E8: Male | F8: 32056 | G8: Indian | H8: 5 | I8: Associate Director | J8: Associate Director | K8: L5 | L8: DEPT009 | M8: OFF003 | N8: EMP0004 | O8: christopher.mehta@accen.com | P8: christopher.mehta1@gmail.com | Q8: +91-9453439902 | R8: +91-9001120422 | S8: 41580 | T8: Permanent | U8: Active | V8: MBA | W8: NIT Trichy | X8: Statistics | Y8: 118.93 | Z8: INR | AA8: 3 Months | AB8: Hybrid | AC8: CC-STR-001 | AD8: 12 | AE8: 16
A9: EMP0008 | B9: Arjun | C9: Pandey | D9: Arjun Pandey | E9: Male | F9: 32087 | G9: Indian | H9: 5 | I9: Associate Director | J9: Associate Director | K9: L5 | L9: DEPT001 | M9: OFF003 | N9: EMP0004 | O9: arjun.pandey@accen.com | P9: arjun.pandey22@gmail.com | Q9: +91-8085653306 | R9: +91-9484543692 | S9: 41720 | T9: Contractor | U9: Active | V9: M.Tech | W9: Mumbai University | X9: Data Science | Y9: 112.99 | Z9: INR | AA9: 3 Months | AB9: On-site | AC9: CC-DATA-001 | AD9: 11 | AE9: 16
A10: EMP0009 | B10: Smita | C10: Chen | D10: Smita Chen | E10: Female | F10: 32175 | G10: Indian | H10: 5 | I10: Associate Director | J10: Associate Director | K10: L5 | L10: DEPT001 | M10: OFF002 | N10: EMP0006 | O10: smita.chen@accen.com | P10: smita.chen8@gmail.com | Q10: +91-7937170674 | R10: +91-7128446479 | S10: 42467 | T10: Permanent | U10: Active | V10: Ph.D | W10: IIT Bangalore | X10: Data Science | Y10: 80.36 | Z10: INR | AA10: 3 Months | AB10: Remote | AC10: CC-DATA-001 | AD10: 10 | AE10: 16
A11: EMP0010 | B11: Aarti | C11: Naik | D11: Aarti Naik | E11: Female | F11: 29032 | G11: Indian | H11: 5 | I11: Associate Director | J11: Associate Director | K11: L5 | L11: DEPT004 | M11: OFF002 | N11: EMP0004 | O11: aarti.naik@accen.com | P11: aarti.naik60@gmail.com | Q11: +91-9986156802 | R11: +91-9758785197 | S11: 41493 | T11: Permanent | U11: Active | V11: M.Sc | W11: NIT Trichy | X11: Computer Science | Y11: 101.55 | Z11: INR | AA11: 3 Months | AB11: Hybrid | AC11: CC-DIG-001 | AD11: 13 | AE11: 17
A12: EMP0011 | B12: Meera | C12: Pandey | D12: Meera Pandey | E12: Female | F12: 29275 | G12: Indian | H12: 5 | I12: Associate Director | J12: Associate Director | K12: L5 | L12: DEPT003 | M12: OFF003 | N12: EMP0004 | O12: meera.pandey@accen.com | P12: meera.pandey13@gmail.com | Q12: +91-7207783823 | R12: +91-9214976638 | S12: 44380 | T12: Permanent | U12: Active | V12: Ph.D | W12: IIT Bombay | X12: Information Technology | Y12: 120.4 | Z12: INR | AA12: 3 Months | AB12: On-site | AC12: CC-SEC-001 | AD12: 5 | AE12: 15
A13: EMP0012 | B13: Sanjay | C13: Subramaniam | D13: Sanjay Subramaniam | E13: Male | F13: 31558 | G13: American | H13: 6 | I13: Senior Manager | J13: Senior Manager | K13: L6 | L13: DEPT009 | M13: OFF002 | N13: EMP0007 | O13: sanjay.subramaniam@accen.com | P13: sanjay.subramaniam94@gmail.com | Q13: +91-9276794022 | R13: +91-9942610311 | S13: 44241 | T13: Contractor | U13: Active | V13: B.Tech | W13: BITS Pilani | X13: Data Science | Y13: 70.93 | Z13: INR | AA13: 2 Months | AB13: Hybrid | AC13: CC-STR-001 | AD13: 5 | AE13: 13
A14: EMP0013 | B14: Arjun | C14: Das | D14: Arjun Das | E14: Male | F14: 32600 | G14: Indian | H14: 6 | I14: Senior Manager | J14: Senior Manager | K14: L6 | L14: DEPT007 | M14: OFF001 | N14: EMP0008 | O14: arjun.das@accen.com | P14: arjun.das24@gmail.com | Q14: +91-7280723939 | R14: +91-7278808011 | S14: 42067 | T14: Permanent | U14: Active | V14: MCA | W14: VIT Vellore | X14: Business Administration | Y14: 56.99 | Z14: INR | AA14: 2 Months | AB14: Hybrid | AC14: CC-SUP-001 | AD14: 10 | AE14: 11
... A152: EMP0151 | B152: Wei | C152: Smith | D152: Wei Smith | E152: Male | F152: 36474 | G152: Indian | H152: 12 | I152: Associate Software Engineer | J152: Associate Software Engineer | K152: L12 | L152: DEPT010 | M152: OFF001 | N152: EMP0064 | O152: wei.smith@accen.com | P152: wei.smith17@gmail.com | Q152: +91-7969405844 | R152: +91-8069992247 | S152: 45396 | T152: Permanent | U152: Active | V152: B.Tech | W152: MIT | X152: Business Administration | Y152: 4.25 | Z152: INR | AA152: 1 Month | AB152: Remote | AC152: CC-AUT-001 | AD152: 2 | AE152: 2

Sheet Employee Skills
A1: Record_ID | B1: Employee_ID | C1: Skill_ID | D1: Proficiency_Level | E1: Years_Experience | F1: Last_Used_Date | G1: Is_Primary_Skill | H1: Assessment_Type
A2: ESK00001 | B2: EMP0001 | C2: SK035 | D2: Expert | E2: 6.5 | F2: 45661 | G2: Yes | H2: Certified
A3: ESK00002 | B3: EMP0001 | C3: SK040 | D3: Beginner | E3: 5.8 | F3: 45218 | G3: No | H3: Certified
A4: ESK00003 | B4: EMP0001 | C4: SK030 | D4: Expert | E4: 6.8 | F4: 45935 | G4: No | H4: Certified
A5: ESK00004 | B5: EMP0001 | C5: SK029 | D5: Advanced | E5: 4.2 | F5: 45111 | G5: No | H5: Self-Assessed
A6: ESK00005 | B6: EMP0001 | C6: SK038 | D6: Intermediate | E6: 2.1 | F6: 46005 | G6: No | H6: Manager-Assessed
A7: ESK00006 | B7: EMP0002 | C7: SK032 | D7: Intermediate | E7: 1.6 | F7: 45217 | G7: Yes | H7: Self-Assessed
A8: ESK00007 | B8: EMP0002 | C8: SK035 | D8: Expert | E8: 7 | F8: 45075 | G8: No | H8: Manager-Assessed
A9: ESK00008 | B9: EMP0002 | C9: SK020 | D9: Expert | E9: 5.5 | F9: 45133 | G9: No | H9: Manager-Assessed
A10: ESK00009 | B10: EMP0002 | C10: SK027 | D10: Intermediate | E10: 1.5 | F10: 45249 | G10: No | H10: Certified
A11: ESK00010 | B11: EMP0002 | C11: SK011 | D11: Expert | E11: 6.4 | F11: 45924 | G11: No | H11: Certified
A12: ESK00011 | B12: EMP0002 | C12: SK038 | D12: Advanced | E12: 5.8 | F12: 45657 | G12: No | H12: Self-Assessed
A13: ESK00012 | B13: EMP0003 | C13: SK031 | D13: Expert | E13: 3.4 | F13: 44993 | G13: Yes | H13: Self-Assessed
... A936: ESK00935 | B936: EMP0151 | C936: SK027 | D936: Intermediate | E936: 1.8 | F936: 45529 | G936: No | H936: Self-Assessed

Sheet Projects
A1: Project_ID | B1: Project_Name | C1: Client_Name | D1: Project_Code | E1: Project_Type | F1: Status | G1: Start_Date | H1: Planned_End_Date | I1: Department_ID | J1: Project_Value_INR | K1: Currency | L1: Delivery_Office_ID | M1: Industry_Vertical
A2: PRJ001 | B2: AI-Powered Credit Risk Engine | C2: HDFC Bank | D2: HDFC-2023-CR | E2: T&M | F2: Completed | G2: 44941 | H2: 45382 | I2: DEPT001 | J2: 45000000 | K2: INR | L2: OFF001 | M2: Banking & Financial Services
A3: PRJ002 | B3: Cloud Data Warehouse Migration | C3: Reliance Industries | D3: RIL-2023-CLD | E3: Fixed Price | F3: Completed | G3: 45017 | H3: 45322 | I3: DEPT002 | J3: 78000000 | K3: INR | L3: OFF001 | M3: Energy & Utilities
A4: PRJ003 | B4: Customer 360 Analytics Platform | C4: Flipkart | D4: FKT-2023-C360 | E4: T&M | F4: Active | G4: 45170 | H4: 45747 | I4: DEPT001 | J4: 92000000 | K4: INR | L4: OFF002 | M4: Retail
A5: PRJ004 | B5: MLOps Platform Implementation | C5: Infosys BPM | D5: INF-2024-ML | E5: Fixed Price | F5: Active | G5: 45323 | H5: 45838 | I5: DEPT001 | J5: 38000000 | K5: INR | L5: OFF004 | M5: Technology
A6: PRJ005 | B6: Real-Time Fraud Detection System | C6: ICICI Bank | D6: ICI-2023-FRD | E6: T&M | F6: Completed | G6: 44986 | H6: 45350 | I6: DEPT001 | J6: 55000000 | K6: INR | L6: OFF003 | M6: Banking & Financial Services
A7: PRJ006 | B7: SAP S/4HANA Greenfield Impl. | C7: Tata Steel | D7: TTS-2023-SAP | E7: Fixed Price | F7: Active | G7: 45108 | H7: 46022 | I7: DEPT005 | J7: 210000000 | K7: INR | L7: OFF003 | M7: Manufacturing
A8: PRJ007 | B8: Zero Trust Security Framework | C8: Wipro Ltd | D8: WIP-2024-SEC | E8: T&M | F8: Active | G8: 45306 | H8: 45777 | I8: DEPT003 | J8: 42000000 | K8: INR | L8: OFF002 | M8: Technology
A9: PRJ008 | B9: Supply Chain Digital Twin | C9: Mahindra & Mahindra | D9: MM-2023-SCM | E9: T&M | F9: Completed | G9: 45078 | H9: 45443 | I9: DEPT007 | J9: 67000000 | K9: INR | L9: OFF004 | M9: Automotive
A10: PRJ009 | B10: Healthcare Data Lake | C10: Apollo Hospitals | D10: APL-2024-DL | E10: Fixed Price | F10: Active | G10: 45352 | H10: 45930 | I10: DEPT001 | J10: 48000000 | K10: INR | L10: OFF003 | M10: Healthcare & Life Sciences
A11: PRJ010 | B11: E-commerce Recommendation Engine | C11: Meesho | D11: MSH-2024-REC | E11: T&M | F11: Active | G11: 45383 | H11: 45747 | I11: DEPT001 | J11: 31000000 | K11: INR | L11: OFF002 | M11: Retail
A12: PRJ011 | B12: Intelligent Document Processing | C12: LIC of India | D12: LIC-2023-IDP | E12: Fixed Price | F12: Completed | G12: 45139 | H12: 45473 | I12: DEPT010 | J12: 29000000 | K12: INR | L12: OFF001 | M12: Insurance
A13: PRJ012 | B13: Azure Data Platform Modernization | C13: Bajaj Finance | D13: BJF-2024-AZ | E13: T&M | F13: Active | G13: 45292 | H13: 45838 | I13: DEPT001 | J13: 72000000 | K13: INR | L13: OFF004 | M13: Banking & Financial Services
... A16: PRJ015 | B16: Predictive Maintenance IoT Analytics | C16: NTPC Limited | D16: NTP-2024-IOT | E16: T&M | F16: Active | G16: 45337 | H16: 45900 | I16: DEPT001 | J16: 58000000 | K16: INR | L16: OFF005 | M16: Energy & Utilities

Sheet Project Assignments
A1: Assignment_ID | B1: Project_ID | C1: Employee_ID | D1: Role_on_Project | E1: Start_Date | F1: End_Date | G1: Allocation_Pct | H1: Billing_Rate_INR | I1: Total_Hours_Billed | J1: Is_Billable | K1: Perf_on_Project
A2: ASN0001 | B2: PRJ001 | C2: EMP0009 | D2: Delivery Director | E2: 44961 | F2: 45358 | G2: 100 | H2: 5854 | I2: 2269 | J2: Yes | K2: Meets
A3: ASN0002 | B3: PRJ001 | C3: EMP0015 | D3: Workstream Lead | E3: 44952 | F3: 45366 | G3: 50 | H3: 2926 | I3: 1183 | J3: Yes | K3: Meets
A4: ASN0003 | B4: PRJ001 | C4: EMP0020 | D4: Technical Manager | E4: 44953 | F4: 45362 | G4: 100 | H4: 2389 | I4: 2337 | J4: Yes | K4: Partially Meets
A5: ASN0004 | B5: PRJ001 | C5: EMP0030 | D5: Module Lead | E5: 44947 | F5: 45368 | G5: 50 | H5: 2135 | I5: 1203 | J5: Yes | K5: Meets
A6: ASN0005 | B6: PRJ001 | C6: EMP0044 | D6: Sr Technical Lead | E6: 44959 | F6: 45377 | G6: 100 | H6: 5076 | I6: 2389 | J6: Yes | K6: Partially Meets
A7: ASN0006 | B7: PRJ001 | C7: EMP0036 | D7: Sub-Module Lead | E7: 44950 | F7: 45368 | G7: 50 | H7: 4432 | I7: 1194 | J7: Yes | K7: Meets
A8: ASN0007 | B8: PRJ001 | C8: EMP0051 | D8: Technical Lead | E8: 44951 | F8: 45369 | G8: 100 | H8: 2952 | I8: 2389 | J8: Yes | K8: Meets
A9: ASN0008 | B9: PRJ001 | C9: EMP0063 | D9: Specialist Lead | E9: 44953 | F9: 45382 | G9: 100 | H9: 2131 | I9: 2451 | J9: Yes | K9: Exceeds
A10: ASN0009 | B10: PRJ001 | C10: EMP0085 | D10: Sr ML Engineer | E10: 44943 | F10: 45373 | G10: 25 | H10: 2308 | I10: 614 | J10: Yes | K10: Meets
A11: ASN0010 | B11: PRJ001 | C11: EMP0082 | D11: Sr ML Engineer | E11: 44970 | F11: 45375 | G11: 25 | H11: 4101 | I11: 579 | J11: No | K11: Exceeds
A12: ASN0011 | B12: PRJ001 | C12: EMP0073 | D12: Senior Developer | E12: 44962 | F12: 45372 | G12: 50 | H12: 2202 | I12: 1171 | J12: Yes | K12: Meets
A13: ASN0012 | B13: PRJ001 | C13: EMP0115 | D13: ML Engineer | E13: 44960 | F13: 45378 | G13: 75 | H13: 1601 | I13: 1791 | J13: Yes | K13: Partially Meets
... A286: ASN0285 | B286: PRJ015 | C286: EMP0147 | D286: Junior Developer | E286: 45354 | F286: 45880 | G286: 25 | H286: 2264 | I286: 751 | J286: Yes | K286: Meets

Sheet Project Skills
A1: Record_ID | B1: Project_ID | C1: Skill_ID | D1: Importance_Level
A2: PSK0001 | B2: PRJ001 | C2: SK001 | D2: Core
A3: PSK0002 | B3: PRJ001 | C3: SK002 | D3: Core
A4: PSK0003 | B4: PRJ001 | C4: SK008 | D4: Core
A5: PSK0004 | B5: PRJ001 | C5: SK006 | D5: Core
A6: PSK0005 | B6: PRJ001 | C6: SK013 | D6: Required
A7: PSK0006 | B7: PRJ001 | C7: SK024 | D7: Required
A8: PSK0007 | B8: PRJ001 | C8: SK033 | D8: Required
A9: PSK0008 | B9: PRJ002 | C9: SK005 | D9: Core
A10: PSK0009 | B10: PRJ002 | C10: SK006 | D10: Core
A11: PSK0010 | B11: PRJ002 | C11: SK016 | D11: Required
A12: PSK0011 | B12: PRJ002 | C12: SK017 | D12: Required
... A77: PSK0076 | B77: PRJ015 | C77: SK036 | D77: Required

Sheet Certifications
A1: Cert_ID | B1: Employee_ID | C1: Certification_Name | D1: Issuing_Body | E1: Related_Skill_ID | F1: Issue_Date | G1: Expiry_Date | H1: Status | I1: Certificate_No
A2: CRT0001 | B2: EMP0001 | C2: Certified Kubernetes Administrator (CKA) | D2: CNCF | E2: SK017 | F2: 45104 | G2: 46200 | H2: Active | I2: CERT-302432
A3: CRT0002 | B3: EMP0004 | C3: Certified Scrum Master (CSM) | D3: Scrum Alliance | E3: SK028 | F3: 45075 | G3: 46171 | H3: Active | I3: CERT-207892
A4: CRT0003 | B4: EMP0004 | C4: Google Professional Data Engineer | D4: Google | E4: SK007 | F4: 44742 | G4: 45838 | H4: Active | I4: CERT-273699
A5: CRT0004 | B5: EMP0005 | C5: Certified Scrum Master (CSM) | D5: Scrum Alliance | E5: SK028 | F5: 45241 | G5: 46337 | H5: Active | I5: CERT-567830
A6: CRT0005 | B6: EMP0005 | C6: Snowflake SnowPro Core | D6: Snowflake | E6: SK014 | F6: 45201 | G6: 46297 | H6: Active | I6: CERT-725297
A7: CRT0006 | B7: EMP0006 | C7: Power BI Data Analyst Associate (PL-300) | D7: Microsoft | E7: SK011 | F7: 44771 | G7: 45867 | H7: Active | I7: CERT-753169
A8: CRT0007 | B8: EMP0011 | C8: Power BI Data Analyst Associate (PL-300) | D8: Microsoft | E8: SK011 | F8: 45306 | G8: 46402 | H8: Active | I8: CERT-275373
A9: CRT0008 | B9: EMP0011 | C9: AWS Certified Data Engineer | D9: Amazon Web Services | E9: SK005 | F9: 43604 | G9: 44700 | H9: Expired | I9: CERT-636196
A10: CRT0009 | B10: EMP0013 | C10: HashiCorp Terraform Associate | D10: HashiCorp | E10: SK018 | F10: 45638 | G10: 46733 | H10: Active | I10: CERT-469364
A11: CRT0010 | B11: EMP0016 | C11: Databricks Associate Developer for Spark | D11: Databricks | E11: SK003 | F11: 44227 | G11: 45322 | H11: Expired | I11: CERT-475122
A12: CRT0011 | B12: EMP0016 | C12: Tableau Desktop Specialist | D12: Salesforce/Tableau | E12: SK012 | F12: 44470 | G12: 45566 | H12: Expired | I12: CERT-176168
A13: CRT0012 | B13: EMP0022 | C13: Certified Scrum Master (CSM) | D13: Scrum Alliance | E13: SK028 | F13: 44813 | G13: 45909 | H13: Active | I13: CERT-324156
... A108: CRT0107 | B108: EMP0150 | C108: AWS Certified Data Engineer | D108: Amazon Web Services | E108: SK005 | F108: 45595 | G108: 46690 | H108: Active | I108: CERT-201568

Sheet Performance Reviews
A1: Review_ID | B1: Employee_ID | C1: Review_Year | D1: Review_Period | E1: Overall_Rating | F1: Goals_Score_5 | G1: Competency_5 | H1: Weighted_Avg_5 | I1: Reviewer_ID | J1: Promotion_Eligible | K1: Increment_Pct | L1: Bonus_Pct | M1: Review_Date
A2: REV00001 | B2: EMP0001 | C2: 2022 | D2: Annual | E2: Exceeds Expectations | F2: 3.8 | G2: 3.5 | H2: 3.6 | I2: EMP0001 | J2: No | K2: 14.5 | L2: 12.8 | M2: 45007
A3: REV00002 | B3: EMP0001 | C3: 2023 | D3: Annual | E3: Meets Expectations | F3: 4.1 | G3: 2.8 | H3: 3.4 | I3: EMP0001 | J3: No | K3: 4.1 | L3: 6.7 | M3: 45369
A4: REV00003 | B4: EMP0001 | C4: 2024 | D4: Annual | E4: Meets Expectations | F4: 3.7 | G4: 3.2 | H4: 3.5 | I4: EMP0001 | J4: No | K4: 6.9 | L4: 7.7 | M4: 45702
A5: REV00004 | B5: EMP0002 | C5: 2022 | D5: Annual | E5: Partially Meets | F5: 2.9 | G5: 3.2 | H5: 3 | I5: EMP0001 | J5: No | K5: 2.3 | L5: 3.3 | M5: 44959
A6: REV00005 | B6: EMP0002 | C6: 2023 | D6: Annual | E6: Partially Meets | F6: 3.4 | G6: 2.8 | H6: 3.1 | I6: EMP0001 | J6: No | K6: 0 | L6: 4.3 | M6: 45303
A7: REV00006 | B7: EMP0002 | C7: 2024 | D7: Annual | E7: Partially Meets | F7: 3.8 | G7: 3.8 | H7: 3.8 | I7: EMP0001 | J7: No | K7: 2.6 | L7: 4.3 | M7: 45666
A8: REV00007 | B8: EMP0003 | C8: 2022 | D8: Annual | E8: Meets Expectations | F8: 4.1 | G8: 4.8 | H8: 4.4 | I8: EMP0002 | J8: No | K8: 8.2 | L8: 9.2 | M8: 45002
A9: REV00008 | B9: EMP0003 | C9: 2023 | D9: Annual | E9: Meets Expectations | F9: 3.8 | G9: 2.8 | H9: 3.3 | I9: EMP0002 | J9: No | K9: 8.8 | L9: 7.8 | M9: 45357
A10: REV00009 | B10: EMP0003 | C10: 2024 | D10: Annual | E10: Meets Expectations | F10: 4.2 | G10: 3.7 | H10: 4 | I10: EMP0002 | J10: No | K10: 5.6 | L10: 11.4 | M10: 45663
A11: REV00010 | B11: EMP0004 | C11: 2022 | D11: Annual | E11: Meets Expectations | F11: 3.5 | G11: 4.9 | H11: 4.2 | I11: EMP0003 | J11: No | K11: 4.3 | L11: 10.2 | M11: 44977
A12: REV00011 | B12: EMP0004 | C12: 2023 | D12: Annual | E12: Meets Expectations | F12: 2.6 | G12: 2.9 | H12: 2.8 | I12: EMP0003 | J12: No | K12: 6.2 | L12: 8.9 | M12: 45337
A13: REV00012 | B13: EMP0004 | C13: 2024 | D13: Annual | E13: Meets Expectations | F13: 3.1 | G13: 4.4 | H13: 3.8 | I13: EMP0003 | J13: No | K13: 6.6 | L13: 5.2 | M13: 45664
... A314: REV00313 | B314: EMP0151 | C314: 2024 | D314: Annual | E314: Meets Expectations | F314: 4.3 | G314: 4.3 | H314: 4.3 | I314: EMP0064 | J314: No | K314: 6 | L314: 8.4 | M314: 45744

Sheet Training Records
A1: Training_ID | B1: Employee_ID | C1: Training_Name | D1: Training_Type | E1: Provider | F1: Related_Skill_ID | G1: Start_Date | H1: End_Date | I1: Duration_Hrs | J1: Status | K1: Score_100 | L1: Is_Mandatory
A2: TRN00001 | B2: EMP0001 | C2: Cloud Architecture Best Practices | D2: External | E2: AWS Training | F2: SK005 | G2: 44781 | H2: 44810 | I2: 4 | J2: Completed | K2: 99 | L2: Yes
A3: TRN00002 | B3: EMP0001 | C3: Cybersecurity Awareness | D3: Internal | E3: Internal L&D | F3: SK016 | G3: 44584 | H3: 44593 | I3: 16 | J3: Enrolled | L3: No
A4: TRN00003 | B4: EMP0002 | C4: Stakeholder Management Workshop | D4: Internal | E4: Internal L&D | F4: SK030 | G4: 44671 | H4: 44683 | I4: 8 | J4: Completed | K4: 87 | L4: No
A5: TRN00004 | B5: EMP0002 | C5: Cybersecurity Awareness | D5: Internal | E5: Internal L&D | F5: SK016 | G5: 44717 | H5: 44726 | I5: 4 | J5: Completed | K5: 79 | L5: Yes
A6: TRN00005 | B6: EMP0002 | C6: Data Governance & Compliance | D6: Internal | E6: Internal L&D | F6: SK002 | G6: 44807 | H6: 44817 | I6: 24 | J6: Completed | K6: 73 | L6: Yes
A7: TRN00006 | B7: EMP0002 | C7: Cloud Architecture Best Practices | D7: External | E7: AWS Training | F7: SK005 | G7: 44624 | H7: 44653 | I7: 24 | J7: Enrolled | L7: Yes
A8: TRN00007 | B8: EMP0003 | C8: Cloud Architecture Best Practices | D8: External | E8: AWS Training | F8: SK005 | G8: 44738 | H8: 44762 | I8: 32 | J8: Completed | K8: 95 | L8: No
A9: TRN00008 | B9: EMP0004 | C9: Generative AI Fundamentals | D9: Internal | E9: Internal L&D | F9: SK010 | G9: 45544 | H9: 45547 | I9: 8 | J9: In Progress | L9: Yes
A10: TRN00009 | B10: EMP0004 | C10: Stakeholder Management Workshop | D10: Internal | E10: Internal L&D | F10: SK030 | G10: 44695 | H10: 44708 | I10: 4 | J10: Completed | K10: 62 | L10: No
A11: TRN00010 | B11: EMP0004 | C11: Cybersecurity Awareness | D11: Internal | E11: Internal L&D | F11: SK016 | G11: 45447 | H11: 45474 | I11: 8 | J11: Completed | K11: 60 | L11: Yes
A12: TRN00011 | B12: EMP0005 | C12: Power BI Advanced Analytics | D12: External | E12: Microsoft Learn | F12: SK011 | G12: 45137 | H12: 45160 | I12: 24 | J12: Completed | K12: 72 | L12: No
A13: TRN00012 | B13: EMP0006 | C13: Python for Data Engineering | D13: External | E13: Udemy / Pluralsight | F13: SK001 | G13: 45118 | H13: 45146 | I13: 40 | J13: Completed | K13: 88 | L13: Yes
A14: TRN00013 | B14: EMP0007 | C14: Docker & Kubernetes Essentials | D14: External | E14: Linux Foundation | F14: SK017 | G14: 45453 | H14: 45471 | I14: 24 | J14: Enrolled | L14: Yes
A15: TRN00014 | B15: EMP0008 | C15: Agile Delivery Masterclass | D15: Internal | E15: Internal L&D | F15: SK028 | G15: 45307 | H15: 45310 | I15: 24 | J15: Completed | K15: 90 | L15: Yes
A16: TRN00015 | B16: EMP0009 | C16: Python for Data Engineering | D16: External | E16: Udemy / Pluralsight | F16: SK001 | G16: 44860 | H16: 44871 | I16: 16 | J16: In Progress | L16: No
A17: TRN00016 | B17: EMP0009 | C17: MLOps & Model Deployment | D17: External | E17: Coursera | F17: SK024 | G17: 44918 | H17: 44937 | I17: 24 | J17: Completed | K17: 82 | L17: No
A18: TRN00017 | B18: EMP0009 | C18: Stakeholder Management Workshop | D18: Internal | E18: Internal L&D | F18: SK030 | G18: 44864 | H18: 44891 | I18: 24 | J18: Completed | K18: 94 | L18: No
A19: TRN00018 | B19: EMP0010 | C19: Spark Performance Tuning | D19: External | E19: Databricks Academy | F19: SK003 | G19: 45080 | H19: 45109 | I19: 16 | J19: Completed | K19: 89 | L19: No
A20: TRN00019 | B20: EMP0010 | C20: Cloud Architecture Best Practices | D20: External | E20: AWS Training | F20: SK005 | G20: 44898 | H20: 44927 | I20: 32 | J20: Completed | K20: 100 | L20: Yes
A21: TRN00020 | B21: EMP0010 | C21: Cybersecurity Awareness | D21: Internal | E21: Internal L&D | F21: SK016 | G21: 45261 | H21: 45279 | I21: 40 | J21: Completed | K21: 70 | L21: Yes
A22: TRN00021 | B22: EMP0011 | C22: Docker & Kubernetes Essentials | D22: External | E22: Linux Foundation | F22: SK017 | G22: 45373 | H22: 45376 | I22: 4 | J22: In Progress | L22: Yes
A23: TRN00022 | B23: EMP0011 | C23: Stakeholder Management Workshop | D23: Internal | E23: Internal L&D | F23: SK030 | G23: 45626 | H23: 45630 | I23: 16 | J23: Completed | K23: 95 | L23: Yes
A24: TRN00023 | B24: EMP0012 | C24: Python for Data Engineering | D24: External | E24: Udemy / Pluralsight | F24: SK001 | G24: 45247 | H24: 45263 | I24: 40 | J24: Completed | K24: 83 | L24: No
A25: TRN00024 | B25: EMP0012 | C25: Stakeholder Management Workshop | D25: Internal | E25: Internal L&D | F25: SK030 | G25: 45633 | H25: 45655 | I25: 8 | J25: In Progress | L25: No
A26: TRN00025 | B26: EMP0013 | C26: Stakeholder Management Workshop | D26: Internal | E26: Internal L&D | F26: SK030 | G26: 45491 | H26: 45496 | I26: 8 | J26: In Progress | L26: Yes
A27: TRN00026 | B27: EMP0013 | C27: Power BI Advanced Analytics | D27: External | E27: Microsoft Learn | F27: SK011 | G27: 45595 | H27: 45621 | I27: 8 | J27: Completed | K27: 64 | L27: No
A28: TRN00027 | B28: EMP0013 | C28: Cloud Architecture Best Practices | D28: External | E28: AWS Training | F28: SK005 | G28: 45057 | H28: 45082 | I28: 8 | J28: Completed | K28: 94 | L28: Yes
A29: TRN00028 | B29: EMP0013 | C29: Leadership Excellence Program | D29: External | E29: Harvard ManageMentor | F29: SK029 | G29: 44953 | H29: 44954 | I29: 16 | J29: Completed | K29: 67 | L29: Yes
A30: TRN00029 | B30: EMP0014 | C30: Docker & Kubernetes Essentials | D30: External | E30: Linux Foundation | F30: SK017 | G30: 44708 | H30: 44711 | I30: 4 | J30: Completed | K30: 87 | L30: No
A31: TRN00030 | B31: EMP0014 | C31: Power BI Advanced Analytics | D31: External | E31: Microsoft Learn | F31: SK011 | G31: 45387 | H31: 45388 | I31: 16 | J31: Completed | K31: 81 | L31: No
A32: TRN00031 | B32: EMP0015 | C32: Leadership Excellence Program | D32: External | E32: Harvard ManageMentor | F32: SK029 | G32: 45541 | H32: 45562 | I32: 4 | J32: Completed | K32: 91 | L32: Yes
A33: TRN00032 | B33: EMP0015 | C33: Agile Delivery Masterclass | D33: Internal | E33: Internal L&D | F33: SK028 | G33: 45585 | H33: 45596 | I33: 16 | J33: Completed | K33: 90 | L33: No
A34: TRN00033 | B34: EMP0015 | C34: Spark Performance Tuning | D34: External | E34: Databricks Academy | F34: SK003 | G34: 44762 | H34: 44776 | I34: 32 | J34: Completed | K34: 82 | L34: No
A35: TRN00034 | B35: EMP0016 | C35: Spark Performance Tuning | D35: External | E35: Databricks Academy | F35: SK003 | G35: 44641 | H35: 44657 | I35: 4 | J35: In Progress | L35: No
A36: TRN00035 | B36: EMP0017 | C36: Advanced SQL Optimization | D36: Internal | E36: Internal L&D | F36: SK002 | G36: 45064 | H36: 45088 | I36: 40 | J36: In Progress | L36: Yes
A37: TRN00036 | B37: EMP0017 | C37: Cloud Architecture Best Practices | D37: External | E37: AWS Training | F37: SK005 | G37: 45493 | H37: 45506 | I37: 8 | J37: In Progress | L37: No
A38: TRN00037 | B38: EMP0017 | C38: Power BI Advanced Analytics | D38: External | E38: Microsoft Learn | F38: SK011 | G38: 44632 | H38: 44643 | I38: 40 | J38: Completed | K38: 88 | L38: Yes
A39: TRN00038 | B39: EMP0018 | C39: Spark Performance Tuning | D39: External | E39: Databricks Academy | F39: SK003 | G39: 44619 | H39: 44649 | I39: 4 | J39: Completed | K39: 92 | L39: Yes
A40: TRN00039 | B40: EMP0018 | C40: Cloud Architecture Best Practices | D40: External | E40: AWS Training | F40: SK005 | G40: 45510 | H40: 45519 | I40: 24 | J40: Completed | K40: 94 | L40: Yes
...
